Workbook
Name Slicer_Country: #N/A
Name Slicer_Country1: #N/A
Name Slicer_Country11: #N/A
Name Slicer_Country2: #N/A
Name Slicer_Country3: #N/A
Name Slicer_Distributor_Name: #N/A
Name Slicer_Distributor_Name1: #N/A
Name Slicer_Group: #N/A
Name Slicer_Group1: #N/A
Name Slicer_Manager: #N/A
Name Slicer_Manager1: #N/A
Name Slicer_Manager2: #N/A
Name Slicer_Manager3: #N/A
Name Slicer_Manager4: #N/A
Name Slicer_Product_Name: #N/A
Name Slicer_Product_Name1: #N/A
Name Slicer_Region: #N/A
Name Slicer_Region1: #N/A
Name Slicer_Region2: #N/A
Name Slicer_Region3: #N/A
Name Slicer_Region31: #N/A

Sheet Wholeseller(Direct Party)
A2: Party Name | B2: Product | C2: Quatity | D2: S.P | E2: Value
A3: Shani Distributor , Khanewal | B3: GTN Cream | C3: 100 | D3: =(8026+9180)/C3 -> 172.06 | E3: =C3*D3 -> 17206
A4: Shani Distributor , Khanewal | B4: Mediscon Syp | C4: 200 | D4: =20020/C4 -> 100.1 | E4: =C4*D4 -> 20020
A5: Naveed Pharma, Haripur | B5: Novagen 1g | C5: 1040 | D5: =98280/1040 -> 94.5 | E5: =C5*D5 -> 98280
A6: Mother Care, Lahore | B6: G-sef 250mg | C6: 28 | D6: 240 | E6: =C6*D6 -> 6720
A7: Blue Ocean, Lahore | B7: GTN Cream | C7: 200 | D7: =32760/C7 -> 163.8 | E7: =C7*D7 -> 32760
A8: Blue Ocean, Lahore | B8: Mediscon Syp | C8: 50 | D8: =5005/C8 -> 100.1 | E8: =C8*D8 -> 5005
A9: ZA Traders, Gujranwala | B9: Mediscon Syp | C9: 300 | D9: 100.1 | E9: =C9*D9 -> 30030
A10: ZA Traders, Gujranwala | B10: Novagen 500mg | C10: 60 | D10: =4800/C10 -> 80 | E10: =C10*D10 -> 4800
A11: ZA Traders, Gujranwala | B11: Medizek Injection 40mg | C11: 50 | D11: =6000/C11 -> 120 | E11: =C11*D11 -> 6000
A12: Total Direct Sale : | E12: =SUM(E3:E11) -> 220821
A13: Total National Sales : | E13: =GETPIVOTDATA("Sales Value",'Combine Sales Distributor Vise'!$A$3) -> 10666150
A14: Total Sales : | E14: =SUM(E12:E13) -> 10886972

Sheet Trade Group LMTD
A1: Group | B1: Medicronis
A2: Category | B2: (All)
A4: Distributor Name | B4: City | C4: 'Yesterday Sale Value | D4: Today Sales Value | E4: 'Difference | F4: 'Target Value | G4: 'Average Target Achv. % | H4: 'LMTD Sales Value | I4: Sum of LMTD Difference2 | J4: Average of LMTD %age
A5: AL-HARAM ENTERPRISES, Kohat | B5: Kohat | C5: 215077 | D5: 215077 | E5: 0 | F5: 657451.31 | G5: 0.41261785 | H5: 327300 | I5: -112223 | J5: -0.31704492
A6: MEHRAN TRADERS, Mardan | B6: Mardan | C6: 55195 | D6: 92799 | E6: 37604 | F6: 550588.18 | G6: 0.2186995 | H6: 63268 | I6: 29531 | J6: 1.3391629
A7: Noor Khan Corporation, Mingora | B7: Mingora | C7: 443672 | D7: 443672 | E7: 0 | F7: 1022820.3 | G7: 0.32422513 | H7: 592501 | I7: -148829 | J7: 0.12924969
A8: Umar Medicine Distribution, Swabi | B8: Swabi | C8: 49790 | D8: 49790 | E8: 0 | F8: 471286.46 | G8: 0.11001177 | H8: 91713 | I8: -41923 | J8: 0.19094896
A9: NEW TAWAKAL ENTERPRISES, ABBT | B9: Abbottabad | C9: 137679 | D9: 150629 | E9: 12950 | F9: 307314 | G9: 0.42147604 | H9: 227423 | I9: -76794 | J9: -0.17224164
A10: M&C Distributor, RWP | B10: Rwp | C10: 79420 | D10: 85890 | E10: 6470 | F10: 360810.68 | G10: 0.13216203 | H10: 77170 | I10: 8720 | J10: 15.521236
A11: MASHAL ENTERPRISES, Bajaur | B11: Bajaur | C11: 253240 | D11: 253240 | E11: 0 | F11: 607425.03 | G11: 0.24195437 | H11: 253005 | I11: 235 | J11: -0.17876801
A12: Wellness Traders, Bhatkela | B12: Bhatkela | C12: 0 | D12: 0 | E12: 0 | F12: 538778.64 | G12: 0 | H12: 7335 | I12: -7335 | J12: -1
A13: Al Makkah Trading Co, Buner | B13: Buner | C13: 295389 | D13: 295389 | E13: 0 | F13: 547999.2 | G13: 0.31384257 | H13: 210956 | I13: 84433 | J13: 0.29932397
A14: CHAUDHARY MEDICINE COMPANY, MWL | B14: Mianwali | C14: 232520 | D14: 277800 | E14: 45280 | F14: 648479.94 | G14: 0.37792619 | H14: 247176 | I14: 30624 | J14: 1.8562365
A15: Evergreen Enterprises, D.I.Khan | B15: D.I.Khan | C15: 450045 | D15: 450045 | E15: 0 | F15: 587264.6 | G15: 0.68721576 | H15: 308400 | I15: 141645 | J15: 1.6538016
A16: NEW SHAHZAIB PHARMACY, Okara | B16: Okara | C16: 268180 | D16: 268180 | E16: 0 | F16: 509925 | G16: 0.50262577 | H16: 298145 | I16: -29965 | J16: -0.092081544
... A30: AQ DISTRIBUTOR,Sargodha | B30: Sargodha | C30: 150784 | D30: 150784 | E30: 0 | F30: 549072.96 | G30: 0.2268459 | H30: 115770 | I30: 35014 | J30: 0.45525289
A31: REHMAN DRUG AGENCY, SKT | B31: Sialkot | C31: 0 | D31: 0 | E31: 0 | F31: 438568.44 | G31: 0 | H31: 0 | I31: 0 | J31: --
A32: Zavion Marketing, Jhang | B32: Jhang | C32: 85719 | D32: 85719 | E32: 0 | F32: 516143.63 | G32: 0.18709078 | H32: 83576 | I32: 2143 | J32: 0.18388287
A33: LIFE CARE, Gujrat | B33: Gujrat | C33: 268476 | D33: 268476 | E33: 0 | F33: 544975.76 | G33: 0.26488193 | H33: 273859 | I33: -5383 | J33: -0.008617079
A34: Pharmarite Distributor, Jehlum | B34: Jhelum | C34: 203040 | D34: 203040 | E34: 0 | F34: 495090.6 | G34: 0.37750204 | H34: 236215 | I34: -33175 | J34: -0.27984604
A35: RELIABLE MEDICOS MIRPURKHAS, MPK | B35: Mirpur Khas | C35: 75161 | D35: 75161 | E35: 0 | F35: 515964 | G35: 0.092540488 | H35: 86415 | I35: -11254 | J35: 0.12012307
A36: ZAFAR & SONS PHARMA, NWS | B36: Nawabshah | C36: 278716 | D36: 278716 | E36: 0 | F36: 484784.52 | G36: 0.61447969 | H36: 200412 | I36: 78304 | J36: 1.9245796
A37: Al Rehman Medical Sources, Lahore | B37: Lahore | C37: 221547 | D37: 221547 | E37: 0 | F37: 1120172.8 | G37: 0.21616425 | H37: 542503 | I37: -320956 | J37: -3.2569572
A38: THE HAMZA TRADERS, Kasur | B38: Kasur | C38: 212565 | D38: 212565 | E38: 0 | F38: 461513.18 | G38: 0.31992826 | H38: 148475 | I38: 64090 | J38: 0.80930266
A39: HAJI NIZAM UD DIN & SONS, Quetta | B39: Quetta | C39: 1736659 | D39: 1744669 | E39: 8010 | F39: 2546675.5 | G39: 0.47193596 | H39: 1635580 | I39: 109089 | J39: 0.45419966
A40: Ayyan Medicine Company, SKP | B40: SKP | C40: 15810 | D40: 15810 | E40: 0 | F40: 454753.17 | G40: 0.028398724 | H40: 147965 | I40: -132155 | J40: -0.151344
A41: Lal Drug Agency, Sibbi | B41: Sibbi | C41: 13760 | D41: 43386 | E41: 29626 | F41: 0 | G41: -- | H41: 44129 | I41: -743 | J41: -0.27429243
A42: SR Traders, Charsadda | B42: Charsadda | C42: 0 | D42: 0 | E42: 0 | F42: 460276.46 | G42: 0 | H42: 0 | I42: 0 | J42: --
A43: Medicamp Distributor, PSW | B43: Peshawar | C43: 9270 | D43: 9270 | E43: 0 | F43: 864245.14 | G43: 0.0060763767 | H43: 35528 | I43: -26258 | J43: -0.755959
A44: Naveed Pharma, Haripur | B44: Haripur | C44: 0 | D44: 0 | E44: 0 | F44: 0 | G44: -- | H44: 429240 | I44: -429240 | J44: -1
A45: AIM Pharma, HYD | B45: Hyderabad | C45: 207317 | D45: 241236 | E45: 33919 | F45: 0 | G45: -- | H45: 109991 | I45: 131245 | J45: 1.9008303
A46: Hamed Pharma, Bannu | B46: Bannu | C46: 209920 | D46: 271000 | E46: 61080 | F46: 421151.84 | G46: 0.26865706 | H46: 342383 | I46: -71383 | J46: 0.032243045
A47: Kamal Medicine Company, Timergara | B47: Timergara | C47: 141683 | D47: 178639 | E47: 36956 | F47: 824606.95 | G47: 0.22587474 | H47: 156395 | I47: 15809 | J47: 3.0827919
A48: Faiz Enterprises, Rajanpur | B48: Rajan pur | C48: 262896 | D48: 272806 | E48: 9910 | F48: 553868.01 | G48: 0.7019154 | H48: 94208 | I48: 178598 | J48: 1.7665012
A49: Hashmani Health Care | B49: Karachi | C49: 308722 | D49: 341592 | E49: 32870 | F49: 0 | G49: -- | H49: 100796 | I49: 240796 | J49: 2.0856487
A50: Bukhari Medicine Company, MBD | B50: MBD | C50: 79102 | D50: 91845 | E50: 12743 | F50: 501874.53 | G50: 0.17632605 | H50: 89472 | I50: 2373 | J50: 1.3605088
A51: Basher Pharma, Gujranwala | B51: Gujranwala | C51: 145567 | D51: 145567 | E51: 0 | F51: 452847.6 | G51: 0.32680102 | H51: 0 | I51: 145567 | J51: --
A52: Ruman Medicine, RYK | B52: R.Y.Khan | C52: 50615 | D52: 50615 | E52: 0 | F52: 230523 | G52: 0.19504024 | H52: 18763 | I52: 31852 | J52: 6.1550139
A53: Global Pharma, SKP | B53: SKP | C53: 10500 | D53: 13650 | E53: 0 | F53: 0 | G53: -- | H53: 0 | I53: 13650 | J53: --
A54: Grand Total | C54: 8912263 | D54: 9261745 | E54: 346332 | F54: 26200092 | G54: 0.26415309 | H54: 9319388 | I54: -64078 | J54: 0.56354665

Sheet Transformer Group LMTD
A1: Group | B1: Transformer
A3: Distributor Name | B3: City | C3: 'Yesterday Sale Value | D3: Today Sales Value | E3: 'Difference | F3: 'Target Value | G3: 'Average Target Achv. % | H3: 'LMTD Sales Value | I3: Sum of LMTD Difference2 | J3: Average of LMTD %age
A4: AL-HARAM ENTERPRISES, Kohat | B4: Kohat | C4: 77562.5 | D4: 77562.5 | E4: 0 | F4: 598302.2 | G4: 0.08061771 | H4: 154700 | I4: -77137.5 | J4: -0.49269603
A5: MEHRAN TRADERS, Mardan | B5: Mardan | C5: -1870 | D5: -1700 | E5: 170 | F5: 0 | G5: -- | H5: 0 | I5: -1700 | J5: --
A6: Noor Khan Corporation, Mingora | B6: Mingora | C6: 0 | D6: 99195 | E6: 99195 | F6: 268175 | G6: 0.44452381 | H6: 1317.5 | I6: 97877.5 | J6: 7.125
A7: Umar Medicine Distribution, Swabi | B7: Swabi | C7: 6120 | D7: 6120 | E7: 0 | F7: 0 | G7: -- | H7: 0 | I7: 6120 | J7: --
A8: NEW TAWAKAL ENTERPRISES, ABBT | B8: Abbottabad | C8: 0 | D8: 0 | E8: 0 | F8: 0 | G8: -- | H8: 0 | I8: 0 | J8: --
A9: M&C Distributor, RWP | B9: Rwp | C9: 0 | D9: 0 | E9: 0 | F9: 0 | G9: -- | H9: 0 | I9: 0 | J9: --
A10: MASHAL ENTERPRISES, Bajaur | B10: Bajaur | C10: 0 | D10: 0 | E10: 0 | F10: 0 | G10: -- | H10: 0 | I10: 0 | J10: --
A11: Wellness Traders, Bhatkela | B11: Bhatkela | C11: 0 | D11: 0 | E11: 0 | F11: 0 | G11: -- | H11: 374 | I11: -374 | J11: -1
A12: Al Makkah Trading Co, Buner | B12: Buner | C12: 0 | D12: 0 | E12: 0 | F12: 0 | G12: -- | H12: 0 | I12: 0 | J12: --
A13: CHAUDHARY MEDICINE COMPANY, MWL | B13: Mianwali | C13: 1016 | D13: 1016 | E13: 0 | F13: 0 | G13: -- | H13: 680 | I13: 336 | J13: 0
A14: Evergreen Enterprises, D.I.Khan | B14: D.I.Khan | C14: 250125.25 | D14: 250125.25 | E14: 0 | F14: 868227.27 | G14: 0.45909533 | H14: 292570 | I14: -42444.75 | J14: -0.22030276
A15: NEW SHAHZAIB PHARMACY, Okara | B15: Okara | C15: 5364 | D15: 5364 | E15: 0 | F15: 0 | G15: -- | H15: 3366 | I15: 1998 | J15: 0.22222222
A16: N&G Enterprises, SWL | B16: SWL | C16: 0 | D16: 0 | E16: 0 | F16: 0 | G16: -- | H16: 0 | I16: 0 | J16: --
A17: AL SHIFA DISTRIBUTOR, Jampur | B17: Jampur | C17: -37315 | D17: -37315 | E17: 0 | F17: 0 | G17: -- | H17: 52402.59 | I17: -89717.59 | J17: -1.4166667
A18: AL Harmain Distribution, D.G Khan | B18: D.G.Khan | C18: 58713.75 | D18: 58713.75 | E18: 0 | F18: 0 | G18: -- | H18: 92259 | I18: -33545.25 | J18: -0.33945869
A19: AYAN PHARMA, Taunsa | B19: Taunsa | C19: 109918 | D19: 109918 | E19: 0 | F19: 0 | G19: -- | H19: 49727.5 | I19: 60190.5 | J19: 1.080632
A20: PUNJAB MEDICINE COMPANY, Layyah | B20: Layyah | C20: 0 | D20: 0 | E20: 0 | F20: 0 | G20: -- | H20: -1360 | I20: 1360 | J20: -1
A21: Wellcome Pharma Distributor, Ali Pur | B21: Ali Pur | C21: 1870 | D21: 2618 | E21: 748 | F21: 0 | G21: -- | H21: 748 | I21: 1870 | J21: 2.5
A22: MRWA ENTERPRISES, BWP | B22: Bahawalpur | C22: 0 | D22: 0 | E22: 0 | F22: 0 | G22: -- | H22: 1700 | I22: -1700 | J22: -1
A23: ALI DISTRIBUTOR, RYK | B23: R.Y.Khan | C23: 35851 | D23: 35851 | E23: 0 | F23: 355765 | G23: 0.13714286 | H23: 175879.5 | I23: -140028.5 | J23: -0.67985657
A24: Royal Medicine Company, Sadiqabad | B24: Sadiq Abad | C24: 0 | D24: 0 | E24: 0 | F24: 0 | G24: -- | H24: 0 | I24: 0 | J24: --
A25: SHAFIQ ENTERPRISES, Khanpur | B25: Khanpur | C25: -7714 | D25: -7714 | E25: 0 | F25: 0 | G25: -- | H25: 12219.5 | I25: -19933.5 | J25: -1.4464286
A26: Hamza Medicine Company, TTS | B26: TTS | C26: 0 | D26: 0 | E26: 0 | F26: 0 | G26: -- | H26: 0 | I26: 0 | J26: --
A27: AMT International, FSD | B27: Faisalabad | C27: 340 | D27: 340 | E27: 0 | F27: 571775.5 | G27: 0.0022675737 | H27: 0 | I27: 340 | J27: --
A28: Chishti Pharma, Multan | B28: Multan | C28: 166680.75 | D28: 166680.75 | E28: 0 | F28: 615570 | G28: 0.4889881 | H28: 5372 | I28: 161308.75 | J28: 0.66666667
A29: AQ DISTRIBUTOR,Sargodha | B29: Sargodha | C29: 1309 | D29: 1309 | E29: 0 | F29: 0 | G29: -- | H29: 561 | I29: 748 | J29: 1.3333333
A30: REHMAN DRUG AGENCY, SKT | B30: Sialkot | C30: 0 | D30: 0 | E30: 0 | F30: 0 | G30: -- | H30: 0 | I30: 0 | J30: --
A31: Zavion Marketing, Jhang | B31: Jhang | C31: 0 | D31: 0 | E31: 0 | F31: 0 | G31: -- | H31: 0 | I31: 0 | J31: --
A32: LIFE CARE, Gujrat | B32: Gujrat | C32: 0 | D32: 0 | E32: 0 | F32: 0 | G32: -- | H32: 2040 | I32: -2040 | J32: -1
A33: Pharmarite Distributor, Jehlum | B33: Jhelum | C33: -178.5 | D33: -178.5 | E33: 0 | F33: 0 | G33: -- | H33: 1309 | I33: -1487.5 | J33: -0.71428571
A34: RELIABLE MEDICOS MIRPURKHAS, MPK | B34: Mirpur Khas | C34: 0 | D34: 0 | E34: 0 | F34: 0 | G34: -- | H34: 0 | I34: 0 | J34: --
A35: ZAFAR & SONS PHARMA, NWS | B35: Nawabshah | C35: 1870 | D35: 1870 | E35: 0 | F35: 0 | G35: -- | H35: 1870 | I35: 0 | J35: 0
A36: Al Rehman Medical Sources, Lahore | B36: Lahore | C36: 187 | D36: 187 | E36: 0 | F36: 0 | G36: -- | H36: 7106 | I36: -6919 | J36: -0.97368421
A37: THE HAMZA TRADERS, Kasur | B37: Kasur | C37: 0 | D37: 0 | E37: 0 | F37: 412058.75 | G37: 0 | H37: 0 | I37: 0 | J37: --
A38: HAJI NIZAM UD DIN & SONS, Quetta | B38: Quetta | C38: 216654 | D38: 216399 | E38: -255 | F38: 0 | G38: -- | H38: 160180 | I38: 56219 | J38: 0.34011905
A39: Ayyan Medicine Company, SKP | B39: SKP | C39: 0 | D39: 0 | E39: 0 | F39: 0 | G39: -- | H39: 4114 | I39: -4114 | J39: -1
A40: Lal Drug Agency, Sibbi | B40: Sibbi | C40: 0 | D40: 0 | E40: 0 | F40: 0 | G40: -- | H40: 0 | I40: 0 | J40: --
A41: SR Traders, Charsadda | B41: Charsadda | C41: 0 | D41: 0 | E41: 0 | F41: 0 | G41: -- | H41: 0 | I41: 0 | J41: --
...

Sheet Combine Sales Distributor Vise
A1: Category | B1: (All)
A3: Sum of Sales Value | C3: Group
A4: Distributor Name | B4: City | C4: Medicronis | D4: Transformer | E4: Grand Total
A5: AL-HARAM ENTERPRISES, Kohat | B5: Kohat | C5: 215077 | D5: 77562.5 | E5: 292639.5
A6: MEHRAN TRADERS, Mardan | B6: Mardan | C6: 92799 | D6: -1700 | E6: 91099
A7: Noor Khan Corporation, Mingora | B7: Mingora | C7: 443672 | D7: 99195 | E7: 542867
A8: Umar Medicine Distribution, Swabi | B8: Swabi | C8: 49790 | D8: 6120 | E8: 55910
A9: NEW TAWAKAL ENTERPRISES, ABBT | B9: Abbottabad | C9: 150629 | D9: 0 | E9: 150629
A10: M&C Distributor, RWP | B10: Rwp | C10: 85890 | D10: 0 | E10: 85890
A11: MASHAL ENTERPRISES, Bajaur | B11: Bajaur | C11: 253240 | D11: 0 | E11: 253240
A12: Wellness Traders, Bhatkela | B12: Bhatkela | C12: 0 | D12: 0 | E12: 0
A13: Al Makkah Trading Co, Buner | B13: Buner | C13: 295389 | D13: 0 | E13: 295389
A14: CHAUDHARY MEDICINE COMPANY, MWL | B14: Mianwali | C14: 277800 | D14: 1016 | E14: 278816
A15: Evergreen Enterprises, D.I.Khan | B15: D.I.Khan | C15: 450045 | D15: 250125.25 | E15: 700170.25
A16: NEW SHAHZAIB PHARMACY, Okara | B16: Okara | C16: 268180 | D16: 5364 | E16: 273544
... A53: Global Pharma, SKP | B53: SKP | C53: 13650 | D53: 0 | E53: 13650
A54: Grand Total | C54: 9261745 | D54: 1404405.5 | E54: 10666150

Sheet Distributor Wise
C3: Values
A4: Distributor Name | B4: City | C4: 'Target Units | D4: April Sales Units | E4: March LMTD Sales Unit | F4: 'Target Value | G4: April Sales Value | H4: 'Target Achv. % | I4: 'LMTD Sales Value | J4: 'LMTD %age | K4: 'Closing Stock Units | L4: 'Stock Value
A5: AL-HARAM ENTERPRISES, Kohat | B5: Kohat | C5: 6682.0475 | D5: 2086 | E5: 2740 | F5: 1255753.5 | G5: 292639.5 | H5: 0.37827301 | I5: 482000 | J5: -0.35757979 | K5: 5574 | L5: 998968.25
A6: MEHRAN TRADERS, Mardan | B6: Mardan | C6: 4998.6062 | D6: 818 | E6: 578 | F6: 550588.18 | G6: 91099 | H6: 0.2186995 | I6: 63268 | J6: 1.3391629 | K6: 3638 | L6: 509282
A7: Noor Khan Corporation, Mingora | B7: Mingora | C7: 8878.6457 | D7: 3997 | E7: 3780 | F7: 1290995.3 | G7: 542867 | H7: 0.34761654 | I7: 593818.5 | J7: 1.0941808 | K7: 6781 | L7: 1039062
A8: Umar Medicine Distribution, Swabi | B8: Swabi | C8: 3995.93 | D8: 508 | E8: 798 | F8: 471286.46 | G8: 55910 | H8: 0.11001177 | I8: 91713 | J8: 0.19094896 | K8: 3015 | L8: 418123
A9: NEW TAWAKAL ENTERPRISES, ABBT | B9: Abbottabad | C9: 2619 | D9: 1236 | E9: 2005 | F9: 307314 | G9: 150629 | H9: 0.42147604 | I9: 227423 | J9: -0.17224164 | K9: 1549 | L9: 165336
A10: M&C Distributor, RWP | B10: Rwp | C10: 3217.6065 | D10: 498 | E10: 516 | F10: 360810.68 | G10: 85890 | H10: 0.13216203 | I10: 77170 | J10: 15.521236 | K10: 709 | L10: 85970
A11: MASHAL ENTERPRISES, Bajaur | B11: Bajaur | C11: 5174.924 | D11: 1906 | E11: 2298 | F11: 607425.03 | G11: 253240 | H11: 0.24195437 | I11: 253005 | J11: -0.17876801 | K11: 3209 | L11: 348320
A12: Wellness Traders, Bhatkela | B12: Bhatkela | C12: 4810.68 | D12: 0 | E12: 101 | F12: 538778.64 | G12: 0 | H12: 0 | I12: 7709 | J12: -1 | K12: 0 | L12: 0
A13: Al Makkah Trading Co, Buner | B13: Buner | C13: 4810.68 | D13: 2752 | E13: 1957 | F13: 547999.2 | G13: 295389 | H13: 0.31384257 | I13: 210956 | J13: 0.29932397 | K13: 2029 | L13: 218341
A14: CHAUDHARY MEDICINE COMPANY, MWL | B14: Mianwali | C14: 5704.48 | D14: 1920 | E14: 1782 | F14: 648479.94 | G14: 278816 | H14: 0.37792619 | I14: 247856 | J14: 1.787487 | K14: 3690 | L14: 452505
A15: Evergreen Enterprises, D.I.Khan | B15: D.I.Khan | C15: 6626.465 | D15: 4591 | E15: 3118 | F15: 1455491.9 | G15: 700170.25 | H15: 0.62384897 | I15: 600970 | J15: 1.2014316 | K15: 4542 | L15: 1007118.2
A16: NEW SHAHZAIB PHARMACY, Okara | B16: Okara | C16: 4135.2 | D16: 2201 | E16: 2401 | F16: 509925 | G16: 273544 | H16: 0.50262577 | I16: 301511 | J16: -0.081942713 | K16: 3192 | L16: 397643
... A30: AQ DISTRIBUTOR,Sargodha | B30: Sargodha | C30: 4870.053 | D30: 1274 | E30: 995 | F30: 549072.96 | G30: 152093 | H30: 0.2268459 | I30: 116331 | J30: 0.48777439 | K30: 2442 | L30: 266275
A31: REHMAN DRUG AGENCY, SKT | B31: Sialkot | C31: 4009.8 | D31: 0 | E31: 0 | F31: 438568.44 | G31: 0 | H31: 0 | I31: 0 | J31: -- | K31: 2212 | L31: 286053
A32: Zavion Marketing, Jhang | B32: Jhang | C32: 4536.068 | D32: 769 | E32: 718 | F32: 516143.63 | G32: 85719 | H32: 0.18709078 | I32: 83576 | J32: 0.18388287 | K32: 1778 | L32: 214036
A33: LIFE CARE, Gujrat | B33: Gujrat | C33: 5038.272 | D33: 2477 | E33: 2535 | F33: 544975.76 | G33: 268476 | H33: 0.26488193 | I33: 275899 | J33: -0.051720684 | K33: 3338 | L33: 369797
A34: Pharmarite Distributor, Jehlum | B34: Jhelum | C34: 4334.52 | D34: 1782 | E34: 1908 | F34: 495090.6 | G34: 202861.5 | H34: 0.37750204 | I34: 237524 | J34: -0.29873472 | K34: 2318 | L34: 264220
A35: RELIABLE MEDICOS MIRPURKHAS, MPK | B35: Mirpur Khas | C35: 4737.72 | D35: 685 | E35: 778 | F35: 515964 | G35: 75161 | H35: 0.092540488 | I35: 86415 | J35: 0.12012307 | K35: 2334 | L35: 280974
A36: ZAFAR & SONS PHARMA, NWS | B36: Nawabshah | C36: 4324.92 | D36: 2572 | E36: 1865 | F36: 484784.52 | G36: 280586 | H36: 0.61447969 | I36: 202282 | J36: 1.8604269 | K36: 1692 | L36: 213325
A37: Al Rehman Medical Sources, Lahore | B37: Lahore | C37: 9621.09 | D37: 1796 | E37: 4636 | F37: 1120172.8 | G37: 221734 | H37: 0.21616425 | I37: 549609 | J37: -3.1656263 | K37: 4997 | L37: 589888
A38: THE HAMZA TRADERS, Kasur | B38: Kasur | C38: 4872.6825 | D38: 1612 | E38: 1039 | F38: 873571.93 | G38: 212565 | H38: 0.25771999 | I38: 148475 | J38: 0.80930266 | K38: 1536 | L38: 189395
A39: HAJI NIZAM UD DIN & SONS, Quetta | B39: Quetta | C39: 22437.45 | D39: 16204 | E39: 15292 | F39: 2546675.5 | G39: 1961068 | H39: 0.47193596 | I39: 1795760 | J39: 0.43835513 | K39: 13284 | L39: 1693345.5
A40: Ayyan Medicine Company, SKP | B40: SKP | C40: 3936.093 | D40: 148 | E40: 1511 | F40: 454753.17 | G40: 15810 | H40: 0.028398724 | I40: 152079 | J40: -0.20792106 | K40: 2854 | L40: 313406
A41: Lal Drug Agency, Sibbi | B41: Sibbi | C41: 0 | D41: 394 | E41: 427 | F41: 0 | G41: 43386 | H41: -- | I41: 44129 | J41: -0.27429243 | K41: 3102 | L41: 331014
A42: SR Traders, Charsadda | B42: Charsadda | C42: 3822.5687 | D42: 0 | E42: 0 | F42: 460276.46 | G42: 0 | H42: 0 | I42: 0 | J42: -- | K42: 1208 | L42: 142797
A43: Medicamp Distributor, PSW | B43: Peshawar | C43: 10515.064 | D43: 59 | E43: 339 | F43: 2425148.5 | G43: -930 | H43: 0.0023051609 | I43: 45728 | J43: -0.83371156 | K43: 3605 | L43: 678893
A44: Naveed Pharma, Haripur | B44: Haripur | C44: 0 | D44: 0 | E44: 4092 | F44: 0 | G44: 0 | H44: -- | I44: 429240 | J44: -1 | K44: 0 | L44: 0
A45: AIM Pharma, HYD | B45: Hyderabad | C45: 0 | D45: 2052 | E45: 1016 | F45: 0 | G45: 262870 | H45: -- | I45: 125912 | J45: 1.5201136 | K45: 3265 | L45: 499584.75
A46: Hamed Pharma, Bannu | B46: Bannu | C46: 5376.572 | D46: 2465 | E46: 3524 | F46: 1174152.3 | G46: 461072.75 | H46: 0.28426953 | I46: 647479.5 | J46: -0.20372096 | K46: 4181 | L46: 817239.5
A47: Kamal Medicine Company, Timergara | B47: Timergara | C47: 6556.073 | D47: 1415 | E47: 1011 | F47: 1079616.9 | G47: 180509 | H47: 0.18308074 | I47: 156395 | J47: 3.0827919 | K47: 2277 | L47: 356790
A48: Faiz Enterprises, Rajanpur | B48: Rajan pur | C48: 4870.053 | D48: 2547 | E48: 873 | F48: 553868.01 | G48: 272806 | H48: 0.7019154 | I48: 99682 | J48: 1.6800481 | K48: 1620 | L48: 190395
A49: Hashmani Health Care | B49: Karachi | C49: 0 | D49: 3090 | E49: 883 | F49: 0 | G49: 347015 | H49: -- | I49: 102666 | J49: 2.0763663 | K49: 2161 | L49: 280901
A50: Bukhari Medicine Company, MBD | B50: MBD | C50: 5055.9565 | D50: 835 | E50: 777 | F50: 795722.03 | G50: 92219 | H50: 0.14273488 | I50: 93212 | J50: 1.2528656 | K50: 1161 | L50: 167518
A51: Basher Pharma, Gujranwala | B51: Gujranwala | C51: 3961.08 | D51: 1219 | E51: 0 | F51: 452847.6 | G51: 145567 | H51: 0.32680102 | I51: 0 | J51: -- | K51: 2780 | L51: 317801
A52: Ruman Medicine, RYK | B52: R.Y.Khan | C52: 2719.56 | D52: 753 | E52: 137 | F52: 586288 | G52: 259485 | H52: 0.23544908 | I52: 18763 | J52: 6.1550139 | K52: 4750 | L52: 946912
A53: Global Pharma, SKP | B53: SKP | C53: 0 | D53: 130 | E53: 0 | F53: 0 | G53: 13650 | H53: -- | I53: 0 | J53: -- | K53: 2900 | L53: 322726
A54: Grand Total | C54: 242918.08 | D54: 83418 | E54: 82088 | F54: 33108492 | G54: 10666150 | H54: 0.26041 | I54: 10680825 | J54: 0.52416654 | K54: 140491 | L54: 19670268

Sheet Product Wise
B3: Values
A4: Product Name | B4: 'Target Units | C4: July Sales Units | D4: June LMTD Sales Unit | E4: 'Target Value | F4: April Sales Value | G4: 'Target Achv. % | H4: 'LMTD Sales Value | I4: 'LMTD %age | J4: 'Stock Unit | K4: 'Stock Value
A5: Nida 200mg/100ml Inf | B5: 33938.566 | C5: 11792 | D5: 14182 | E5: 3543751.5 | F5: 1232880 | G5: 0.23360951 | H5: 1482828 | I5: 0.018490899 | J5: 11046 | K5: 1156839
A6: Novagen 1g | B6: 28693.469 | C6: 6129 | D6: 9915 | E6: 2954212.4 | F6: 634746 | G6: 0.20161199 | H6: 1034684 | I6: 0.0026964195 | J6: 8272 | K6: 852155
A7: Novagen 500mg | B7: 19416.143 | C7: 2163 | D7: 1746 | E7: 1512205.2 | F7: 170710 | G7: 0.12030888 | H7: 136876 | I7: 0.68674417 | J7: 6178 | K7: 486670
A8: Salberry Sachet 10s | B8: 204 | C8: 98 | D8: 166 | E8: 21420 | F8: 10290 | G8: 0 | H8: 17430 | I8: -0.39335241 | J8: 577 | K8: 60585
A9: Mediscon Syp 120ml | B9: 22863.6 | C9: 17326 | D9: 15184 | E9: 2496312 | F9: 1896710 | G9: 0.66111308 | H9: 1660170 | I9: 0.55803378 | J9: 11012 | K9: 1203060
A10: Trenmed Tab | B10: 1627 | C10: 795 | D10: 677 | E10: 1106360 | F10: 540600 | G10: 0.47560606 | H10: 460360 | I10: 1.4030909 | J10: 1097 | K10: 745960
A11: Gee T.N Ointment | B11: 10519 | C11: 4593 | D11: 4142 | E11: 1861884 | F11: 819780 | G11: 0.42400348 | H11: 739810 | I11: 1.3356426 | J11: 3990 | K11: 711560
A12: Clan Plus Syp | B12: 2632 | C12: 1004 | D12: 659 | E12: 671160 | F12: 256020 | G12: 0.325 | H12: 168045 | I12: 1.1311831 | J12: 1221 | K12: 311355
A13: Medelac Syp 120ml | B13: 6656 | C13: 4630 | D13: 4504 | E13: 699600 | F13: 486280 | G13: 0.61422552 | H13: 473110 | I13: 0.25609883 | J13: 5883 | K13: 618365
A14: Berry Flow Sachet | B14: 4381.4553 | C14: 4090 | D14: 3819 | E14: 503867.35 | F14: 470350 | G14: 0.69869345 | H14: 439185 | I14: 0.17832632 | J14: 4410 | K14: 507150
A15: Grand Total | B15: 130931.23 | C15: 52620 | D15: 54994 | E15: 15370772 | F15: 6518366 | G15: 0.42548302 | H15: 6612498 | I15: 0.46966163 | J15: 53686 | K15: 6653699

Sheet DATA
A3: Distributor Name | B3: City | C3: Region | D3: Country | E3: Category | F3: Group | G3: Manager | H3: Product Name | I3: S.P | J3: Sales Units | K3: Closing Stock | L3: Sales Value | M3: Stock Value | N3: Yesterday | O3: Yesterday Sale Value | P3: Difference | Q3: Target Units | R3: Target Value | S3: Target Achv. % | T3: LMTD Sales Unit | U3: LMTD Difference | V3: LMTD Sales Value | W3: LMTD Difference | X3: LMTD %age | Y3: Inventory | Z3: Order | AA3: Order Value | AB3: Excess Stock | AC3: Excess Stock Value | AD3: Inventory Value | AE3: Transit
A4: AL-HARAM ENTERPRISES, Kohat | B4: =IFERROR(VLOOKUP(A4,'Distributor List'!$A$2:$D$77,2,0),"-") -> Kohat | C4: =IFERROR(VLOOKUP(A4,'Distributor List'!$A$2:$D$77,3,0),"-") -> North-1 | D4: =IFERROR(VLOOKUP(A4,'Distributor List'!$A$2:$F$77,6,0),"-") -> Pak-2 | E4: =IFERROR(VLOOKUP(A4,'Distributor List'!$A$2:$D$77,4,0),"-") -> Distributor | F4: =IFERROR(VLOOKUP(H4,'Price List'!$A$2:$H$109,8,0),"-") -> Transformer | G4: =IFERROR(VLOOKUP(A4,'Distributor List'!$A$2:$E$77,5,0),"-") -> Bannu Vacant | H4: Novagen 250mg T | I4: 161.5 | J4: 20 | K4: 384 | L4: =J4*I4 -> 3230 | M4: =K4*I4 -> 62016 | N4: 20 | O4: =N4*I4 -> 3230 | P4: =L4-O4 -> 0 | Q4: 218.025 | R4: =Q4*I4 -> 35211.037 | S4: =IFERROR(L4/R4,"-") -> 0.091732599 | T4: 0 | U4: =J4-T4 -> 20 | V4: =T4*I4 -> 0 | W4: =L4-V4 -> 3230 | X4: =IFERROR(L4/V4-1,"-") -> - | Y4: =(J4)/1*1.5 -> 30 | Z4: =IF(Y4>K4,Y4-K4,0) -> 0 | AA4: =Z4*I4 -> 0 | AB4: =IF(Y4<K4,K4-Y4,0) -> 354 | AC4: =AB4*I4 -> 57171 | AD4: =Y4*I4 -> 4845 | AE4: 0
A5: AL-HARAM ENTERPRISES, Kohat | B5: =IFERROR(VLOOKUP(A5,'Distributor List'!$A$2:$D$77,2,0),"-") -> Kohat | C5: =IFERROR(VLOOKUP(A5,'Distributor List'!$A$2:$D$77,3,0),"-") -> North-1 | D5: =IFERROR(VLOOKUP(A5,'Distributor List'!$A$2:$F$77,6,0),"-") -> Pak-2 | E5: =IFERROR(VLOOKUP(A5,'Distributor List'!$A$2:$D$77,4,0),"-") -> Distributor | F5: =IFERROR(VLOOKUP(H5,'Price List'!$A$2:$H$109,8,0),"-") -> Transformer | G5: =IFERROR(VLOOKUP(A5,'Distributor List'!$A$2:$E$77,5,0),"-") -> Bannu Vacant | H5: Novagen 500mg T | I5: 242.25 | J5: 40 | K5: 417 | L5: =J5*I5 -> 9690 | M5: =K5*I5 -> 101018.25 | N5: 40 | O5: =N5*I5 -> 9690 | P5: =L5-O5 -> 0 | Q5: 700.4475 | R5: =Q5*I5 -> 169683.41 | S5: =IFERROR(L5/R5,"-") -> 0.05710635 | T5: 20 | U5: =J5-T5 -> 20 | V5: =T5*I5 -> 4845 | W5: =L5-V5 -> 4845 | X5: =IFERROR(L5/V5-1,"-") -> 1 | Y5: =(J5)/1*1.5 -> 60 | Z5: =IF(Y5>K5,Y5-K5,0) -> 0 | AA5: =Z5*I5 -> 0 | AB5: =IF(Y5<K5,K5-Y5,0) -> 357 | AC5: =AB5*I5 -> 86483.25 | AD5: =Y5*I5 -> 14535 | AE5: 0
A6: AL-HARAM ENTERPRISES, Kohat | B6: =IFERROR(VLOOKUP(A6,'Distributor List'!$A$2:$D$77,2,0),"-") -> Kohat | C6: =IFERROR(VLOOKUP(A6,'Distributor List'!$A$2:$D$77,3,0),"-") -> North-1 | D6: =IFERROR(VLOOKUP(A6,'Distributor List'!$A$2:$F$77,6,0),"-") -> Pak-2 | E6: =IFERROR(VLOOKUP(A6,'Distributor List'!$A$2:$D$77,4,0),"-") -> Distributor | F6: =IFERROR(VLOOKUP(H6,'Price List'!$A$2:$H$109,8,0),"-") -> Transformer | G6: =IFERROR(VLOOKUP(A6,'Distributor List'!$A$2:$E$77,5,0),"-") -> Bannu Vacant | H6: Novagen 1g T | I6: 446.25 | J6: 82 | K6: 208 | L6: =J6*I6 -> 36592.5 | M6: =K6*I6 -> 92820 | N6: 82 | O6: =N6*I6 -> 36592.5 | P6: =L6-O6 -> 0 | Q6: 881.586 | R6: =Q6*I6 -> 393407.75 | S6: =IFERROR(L6/R6,"-") -> 0.093014181 | T6: 190 | U6: =J6-T6 -> -108 | V6: =T6*I6 -> 84787.5 | W6: =L6-V6 -> -48195 | X6: =IFERROR(L6/V6-1,"-") -> -0.56842105 | Y6: =(J6)/1*1.5 -> 123 | Z6: =IF(Y6>K6,Y6-K6,0) -> 0 | AA6: =Z6*I6 -> 0 | AB6: =IF(Y6<K6,K6-Y6,0) -> 85 | AC6: =AB6*I6 -> 37931.25 | AD6: =Y6*I6 -> 54888.75 | AE6: 0
A7: AL-HARAM ENTERPRISES, Kohat | B7: =IFERROR(VLOOKUP(A7,'Distributor List'!$A$2:$D$77,2,0),"-") -> Kohat | C7: =IFERROR(VLOOKUP(A7,'Distributor List'!$A$2:$D$77,3,0),"-") -> North-1 | D7: =IFERROR(VLOOKUP(A7,'Distributor List'!$A$2:$F$77,6,0),"-") -> Pak-2 | E7: =IFERROR(VLOOKUP(A7,'Distributor List'!$A$2:$D$77,4,0),"-") -> Distributor | F7: =IFERROR(VLOOKUP(H7,'Price List'!$A$2:$H$109,8,0),"-") -> Transformer | G7: =IFERROR(VLOOKUP(A7,'Distributor List'!$A$2:$E$77,5,0),"-") -> Bannu Vacant | H7: Ectafin 1G | I7: 297.5 | J7: 0 | K7: 80 | L7: =J7*I7 -> 0 | M7: =K7*I7 -> 23800 | N7: 0 | O7: =N7*I7 -> 0 | P7: =L7-O7 -> 0 | Q7: 0 | R7: =Q7*I7 -> 0 | S7: =IFERROR(L7/R7,"-") -> - | T7: 70 | U7: =J7-T7 -> -70 | V7: =T7*I7 -> 20825 | W7: =L7-V7 -> -20825 | X7: =IFERROR(L7/V7-1,"-") -> -1 | Y7: =(J7)/1*1.5 -> 0 | Z7: =IF(Y7>K7,Y7-K7,0) -> 0 | AA7: =Z7*I7 -> 0 | AB7: =IF(Y7<K7,K7-Y7,0) -> 80 | AC7: =AB7*I7 -> 23800 | AD7: =Y7*I7 -> 0 | AE7: 0
A8: AL-HARAM ENTERPRISES, Kohat | B8: =IFERROR(VLOOKUP(A8,'Distributor List'!$A$2:$D$77,2,0),"-") -> Kohat | C8: =IFERROR(VLOOKUP(A8,'Distributor List'!$A$2:$D$77,3,0),"-") -> North-1 | D8: =IFERROR(VLOOKUP(A8,'Distributor List'!$A$2:$F$77,6,0),"-") -> Pak-2 | E8: =IFERROR(VLOOKUP(A8,'Distributor List'!$A$2:$D$77,4,0),"-") -> Distributor | F8: =IFERROR(VLOOKUP(H8,'Price List'!$A$2:$H$109,8,0),"-") -> Transformer | G8: =IFERROR(VLOOKUP(A8,'Distributor List'!$A$2:$E$77,5,0),"-") -> Bannu Vacant | H8: Ectafin 2G | I8: 429.25 | J8: 0 | K8: 80 | L8: =J8*I8 -> 0 | M8: =K8*I8 -> 34340 | N8: 0 | O8: =N8*I8 -> 0 | P8: =L8-O8 -> 0 | Q8: 0 | R8: =Q8*I8 -> 0 | S8: =IFERROR(L8/R8,"-") -> - | T8: 70 | U8: =J8-T8 -> -70 | V8: =T8*I8 -> 30047.5 | W8: =L8-V8 -> -30047.5 | X8: =IFERROR(L8/V8-1,"-") -> -1 | Y8: =(J8)/1*1.5 -> 0 | Z8: =IF(Y8>K8,Y8-K8,0) -> 0 | AA8: =Z8*I8 -> 0 | AB8: =IF(Y8<K8,K8-Y8,0) -> 80 | AC8: =AB8*I8 -> 34340 | AD8: =Y8*I8 -> 0 | AE8: 0
A9: AL-HARAM ENTERPRISES, Kohat | B9: =IFERROR(VLOOKUP(A9,'Distributor List'!$A$2:$D$77,2,0),"-") -> Kohat | C9: =IFERROR(VLOOKUP(A9,'Distributor List'!$A$2:$D$77,3,0),"-") -> North-1 | D9: =IFERROR(VLOOKUP(A9,'Distributor List'!$A$2:$F$77,6,0),"-") -> Pak-2 | E9: =IFERROR(VLOOKUP(A9,'Distributor List'!$A$2:$D$77,4,0),"-") -> Distributor | F9: =IFERROR(VLOOKUP(H9,'Price List'!$A$2:$H$109,8,0),"-") -> Medicronis | G9: =IFERROR(VLOOKUP(A9,'Distributor List'!$A$2:$E$77,5,0),"-") -> Bannu Vacant | H9: Lancix Inj. 10s | I9: 270 | J9: 31 | K9: 463 | L9: =J9*I9 -> 8370 | M9: =K9*I9 -> 125010 | N9: 31 | O9: =N9*I9 -> 8370 | P9: =L9-O9 -> 0 | Q9: 388.773 | R9: =Q9*I9 -> 104968.71 | S9: =IFERROR(L9/R9,"-") -> 0.079738048 | T9: 96 | U9: =J9-T9 -> -65 | V9: =T9*I9 -> 25920 | W9: =L9-V9 -> -17550 | X9: =IFERROR(L9/V9-1,"-") -> -0.67708333 | Y9: =(J9)/1*1.5 -> 46.5 | Z9: =IF(Y9>K9,Y9-K9,0) -> 0 | AA9: =Z9*I9 -> 0 | AB9: =IF(Y9<K9,K9-Y9,0) -> 416.5 | AC9: =AB9*I9 -> 112455 | AD9: =Y9*I9 -> 12555 | AE9: 0
A10: AL-HARAM ENTERPRISES, Kohat | B10: =IFERROR(VLOOKUP(A10,'Distributor List'!$A$2:$D$77,2,0),"-") -> Kohat | C10: =IFERROR(VLOOKUP(A10,'Distributor List'!$A$2:$D$77,3,0),"-") -> North-1 | D10: =IFERROR(VLOOKUP(A10,'Distributor List'!$A$2:$F$77,6,0),"-") -> Pak-2 | E10: =IFERROR(VLOOKUP(A10,'Distributor List'!$A$2:$D$77,4,0),"-") -> Distributor | F10: =IFERROR(VLOOKUP(H10,'Price List'!$A$2:$H$109,8,0),"-") -> Medicronis | G10: =IFERROR(VLOOKUP(A10,'Distributor List'!$A$2:$E$77,5,0),"-") -> Bannu Vacant | H10: Lancix Inj. 25s | I10: 670 | J10: 6 | K10: 188 | L10: =J10*I10 -> 4020 | M10: =K10*I10 -> 125960 | N10: 6 | O10: =N10*I10 -> 4020 | P10: =L10-O10 -> 0 | Q10: 84.21 | R10: =Q10*I10 -> 56420.7 | S10: =IFERROR(L10/R10,"-") -> 0.071250445 | T10: 101 | U10: =J10-T10 -> -95 | V10: =T10*I10 -> 67670 | W10: =L10-V10 -> -63650 | X10: =IFERROR(L10/V10-1,"-") -> -0.94059406 | Y10: =(J10)/1*1.5 -> 9 | Z10: =IF(Y10>K10,Y10-K10,0) -> 0 | AA10: =Z10*I10 -> 0 | AB10: =IF(Y10<K10,K10-Y10,0) -> 179 | AC10: =AB10*I10 -> 119930 | AD10: =Y10*I10 -> 6030 | AE10: 0
A11: AL-HARAM ENTERPRISES, Kohat | B11: =IFERROR(VLOOKUP(A11,'Distributor List'!$A$2:$D$77,2,0),"-") -> Kohat | C11: =IFERROR(VLOOKUP(A11,'Distributor List'!$A$2:$D$77,3,0),"-") -> North-1 | D11: =IFERROR(VLOOKUP(A11,'Distributor List'!$A$2:$F$77,6,0),"-") -> Pak-2 | E11: =IFERROR(VLOOKUP(A11,'Distributor List'!$A$2:$D$77,4,0),"-") -> Distributor | F11: =IFERROR(VLOOKUP(H11,'Price List'!$A$2:$H$109,8,0),"-") -> Medicronis | G11: =IFERROR(VLOOKUP(A11,'Distributor List'!$A$2:$E$77,5,0),"-") -> Bannu Vacant | H11: G.Tax 250mg | I11: 58 | J11: 0 | K11: 235 | L11: =J11*I11 -> 0 | M11: =K11*I11 -> 13630 | N11: 0 | O11: =N11*I11 -> 0 | P11: =L11-O11 -> 0 | Q11: 81 | R11: =Q11*I11 -> 4698 | S11: =IFERROR(L11/R11,"-") -> 0 | T11: 0 | U11: =J11-T11 -> 0 | V11: =T11*I11 -> 0 | W11: =L11-V11 -> 0 | X11: =IFERROR(L11/V11-1,"-") -> - | Y11: =(J11)/1*1.5 -> 0 | Z11: =IF(Y11>K11,Y11-K11,0) -> 0 | AA11: =Z11*I11 -> 0 | AB11: =IF(Y11<K11,K11-Y11,0) -> 235 | AC11: =AB11*I11 -> 13630 | AD11: =Y11*I11 -> 0 | AE11: 0
A12: AL-HARAM ENTERPRISES, Kohat | B12: =IFERROR(VLOOKUP(A12,'Distributor List'!$A$2:$D$77,2,0),"-") -> Kohat | C12: =IFERROR(VLOOKUP(A12,'Distributor List'!$A$2:$D$77,3,0),"-") -> North-1 | D12: =IFERROR(VLOOKUP(A12,'Distributor List'!$A$2:$F$77,6,0),"-") -> Pak-2 | E12: =IFERROR(VLOOKUP(A12,'Distributor List'!$A$2:$D$77,4,0),"-") -> Distributor | F12: =IFERROR(VLOOKUP(H12,'Price List'!$A$2:$H$109,8,0),"-") -> Medicronis | G12: =IFERROR(VLOOKUP(A12,'Distributor List'!$A$2:$E$77,5,0),"-") -> Bannu Vacant | H12: G.Tax 500mg | I12: 72 | J12: 0 | K12: 40 | L12: =J12*I12 -> 0 | M12: =K12*I12 -> 2880 | N12: 0 | O12: =N12*I12 -> 0 | P12: =L12-O12 -> 0 | Q12: 81 | R12: =Q12*I12 -> 5832 | S12: =IFERROR(L12/R12,"-") -> 0 | T12: 10 | U12: =J12-T12 -> -10 | V12: =T12*I12 -> 720 | W12: =L12-V12 -> -720 | X12: =IFERROR(L12/V12-1,"-") -> -1 | Y12: =(J12)/1*1.5 -> 0 | Z12: =IF(Y12>K12,Y12-K12,0) -> 0 | AA12: =Z12*I12 -> 0 | AB12: =IF(Y12<K12,K12-Y12,0) -> 40 | AC12: =AB12*I12 -> 2880 | AD12: =Y12*I12 -> 0 | AE12: 0
A13: AL-HARAM ENTERPRISES, Kohat | B13: =IFERROR(VLOOKUP(A13,'Distributor List'!$A$2:$D$77,2,0),"-") -> Kohat | C13: =IFERROR(VLOOKUP(A13,'Distributor List'!$A$2:$D$77,3,0),"-") -> North-1 | D13: =IFERROR(VLOOKUP(A13,'Distributor List'!$A$2:$F$77,6,0),"-") -> Pak-2 | E13: =IFERROR(VLOOKUP(A13,'Distributor List'!$A$2:$D$77,4,0),"-") -> Distributor | F13: =IFERROR(VLOOKUP(H13,'Price List'!$A$2:$H$109,8,0),"-") -> Medicronis | G13: =IFERROR(VLOOKUP(A13,'Distributor List'!$A$2:$E$77,5,0),"-") -> Bannu Vacant | H13: G.Tax 1G | I13: 112 | J13: 186 | K13: 386 | L13: =J13*I13 -> 20832 | M13: =K13*I13 -> 43232 | N13: 186 | O13: =N13*I13 -> 20832 | P13: =L13-O13 -> 0 | Q13: 64.8 | R13: =Q13*I13 -> 7257.6 | S13: =IFERROR(L13/R13,"-") -> 2.8703704 | T13: 0 | U13: =J13-T13 -> 186 | V13: =T13*I13 -> 0 | W13: =L13-V13 -> 20832 | X13: =IFERROR(L13/V13-1,"-") -> - | Y13: =(J13)/1*1.5 -> 279 | Z13: =IF(Y13>K13,Y13-K13,0) -> 0 | AA13: =Z13*I13 -> 0 | AB13: =IF(Y13<K13,K13-Y13,0) -> 107 | AC13: =AB13*I13 -> 11984 | AD13: =Y13*I13 -> 31248 | AE13: 0
A14: AL-HARAM ENTERPRISES, Kohat | B14: =IFERROR(VLOOKUP(A14,'Distributor List'!$A$2:$D$77,2,0),"-") -> Kohat | C14: =IFERROR(VLOOKUP(A14,'Distributor List'!$A$2:$D$77,3,0),"-") -> North-1 | D14: =IFERROR(VLOOKUP(A14,'Distributor List'!$A$2:$F$77,6,0),"-") -> Pak-2 | E14: =IFERROR(VLOOKUP(A14,'Distributor List'!$A$2:$D$77,4,0),"-") -> Distributor | F14: =IFERROR(VLOOKUP(H14,'Price List'!$A$2:$H$109,8,0),"-") -> Medicronis | G14: =IFERROR(VLOOKUP(A14,'Distributor List'!$A$2:$E$77,5,0),"-") -> Bannu Vacant | H14: G-Sef 125mg Susp 60ml | I14: 140 | J14: 20 | K14: 154 | L14: =J14*I14 -> 2800 | M14: =K14*I14 -> 21560 | N14: 20 | O14: =N14*I14 -> 2800 | P14: =L14-O14 -> 0 | Q14: 63.04 | R14: =Q14*I14 -> 8825.6 | S14: =IFERROR(L14/R14,"-") -> 0.31725888 | T14: 0 | U14: =J14-T14 -> 20 | V14: =T14*I14 -> 0 | W14: =L14-V14 -> 2800 | X14: =IFERROR(L14/V14-1,"-") -> - | Y14: =(J14)/1*1.5 -> 30 | Z14: =IF(Y14>K14,Y14-K14,0) -> 0 | AA14: =Z14*I14 -> 0 | AB14: =IF(Y14<K14,K14-Y14,0) -> 124 | AC14: =AB14*I14 -> 17360 | AD14: =Y14*I14 -> 4200 | AE14: 0
A15: AL-HARAM ENTERPRISES, Kohat | B15: =IFERROR(VLOOKUP(A15,'Distributor List'!$A$2:$D$77,2,0),"-") -> Kohat | C15: =IFERROR(VLOOKUP(A15,'Distributor List'!$A$2:$D$77,3,0),"-") -> North-1 | D15: =IFERROR(VLOOKUP(A15,'Distributor List'!$A$2:$F$77,6,0),"-") -> Pak-2 | E15: =IFERROR(VLOOKUP(A15,'Distributor List'!$A$2:$D$77,4,0),"-") -> Distributor | F15: =IFERROR(VLOOKUP(H15,'Price List'!$A$2:$H$109,8,0),"-") -> Medicronis | G15: =IFERROR(VLOOKUP(A15,'Distributor List'!$A$2:$E$77,5,0),"-") -> Bannu Vacant | H15: G-Sef 250mg Susp 60ml | I15: 199 | J15: 0 | K15: 0 | L15: =J15*I15 -> 0 | M15: =K15*I15 -> 0 | N15: 0 | O15: =N15*I15 -> 0 | P15: =L15-O15 -> 0 | Q15: 52.904 | R15: =Q15*I15 -> 10527.896 | S15: =IFERROR(L15/R15,"-") -> 0 | T15: 0 | U15: =J15-T15 -> 0 | V15: =T15*I15 -> 0 | W15: =L15-V15 -> 0 | X15: =IFERROR(L15/V15-1,"-") -> - | Y15: =(J15)/1*1.5 -> 0 | Z15: =IF(Y15>K15,Y15-K15,0) -> 0 | AA15: =Z15*I15 -> 0 | AB15: =IF(Y15<K15,K15-Y15,0) -> 0 | AC15: =AB15*I15 -> 0 | AD15: =Y15*I15 -> 0 | AE15: 0
... A42: AL-HARAM ENTERPRISES, Kohat | B42: =IFERROR(VLOOKUP(A42,'Distributor List'!$A$2:$D$77,2,0),"-") -> Kohat | C42: =IFERROR(VLOOKUP(A42,'Distributor List'!$A$2:$D$77,3,0),"-") -> North-1 | D42: =IFERROR(VLOOKUP(A42,'Distributor List'!$A$2:$F$77,6,0),"-") -> Pak-2 | E42: =IFERROR(VLOOKUP(A42,'Distributor List'!$A$2:$D$77,4,0),"-") -> Distributor | F42: =IFERROR(VLOOKUP(H42,'Price List'!$A$2:$H$109,8,0),"-") -> Medicronis | G42: =IFERROR(VLOOKUP(A42,'Distributor List'!$A$2:$E$77,5,0),"-") -> Bannu Vacant | H42: Medelac Syp 120ml | I42: 105 | J42: 63 | K42: 47 | L42: =J42*I42 -> 6615 | M42: =K42*I42 -> 4935 | N42: 63 | O42: =N42*I42 -> 6615 | P42: =L42-O42 -> 0 | Q42: 144 | R42: =Q42*I42 -> 15120 | S42: =IFERROR(L42/R42,"-") -> 0.4375 | T42: 75 | U42: =J42-T42 -> -12 | V42: =T42*I42 -> 7875 | W42: =L42-V42 -> -1260 | X42: =IFERROR(L42/V42-1,"-") -> -0.16 | Y42: =(J42)/1*1.5 -> 94.5 | Z42: =IF(Y42>K42,Y42-K42,0) -> 47.5 | AA42: =Z42*I42 -> 4987.5 | AB42: =IF(Y42<K42,K42-Y42,0) -> 0 | AC42: =AB42*I42 -> 0 | AD42: =Y42*I42 -> 9922.5 | AE42: 0
A43: AL-HARAM ENTERPRISES, Kohat | B43: =IFERROR(VLOOKUP(A43,'Distributor List'!$A$2:$D$77,2,0),"-") -> Kohat | C43: =IFERROR(VLOOKUP(A43,'Distributor List'!$A$2:$D$77,3,0),"-") -> North-1 | D43: =IFERROR(VLOOKUP(A43,'Distributor List'!$A$2:$F$77,6,0),"-") -> Pak-2 | E43: =IFERROR(VLOOKUP(A43,'Distributor List'!$A$2:$D$77,4,0),"-") -> Distributor | F43: =IFERROR(VLOOKUP(H43,'Price List'!$A$2:$H$109,8,0),"-") -> Medicronis | G43: =IFERROR(VLOOKUP(A43,'Distributor List'!$A$2:$E$77,5,0),"-") -> Bannu Vacant | H43: Medizek 20mg | I43: 90 | J43: 0 | K43: 0 | L43: =J43*I43 -> 0 | M43: =K43*I43 -> 0 | N43: 0 | O43: =N43*I43 -> 0 | P43: =L43-O43 -> 0 | Q43: 0 | R43: 0 | S43: =IFERROR(L43/R43,"-") -> - | T43: 0 | U43: 0 | V43: =T43*I43 -> 0 | W43: =L43-V43 -> 0 | X43: =IFERROR(L43/V43-1,"-") -> - | Y43: =(J43)/1*1.5 -> 0 | Z43: =IF(Y43>K43,Y43-K43,0) -> 0 | AA43: =Z43*I43 -> 0 | AB43: =IF(Y43<K43,K43-Y43,0) -> 0 | AC43: =AB43*I43 -> 0 | AD43: =Y43*I43 -> 0 | AE43: 0
A44: AL-HARAM ENTERPRISES, Kohat | B44: =IFERROR(VLOOKUP(A44,'Distributor List'!$A$2:$D$77,2,0),"-") -> Kohat | C44: =IFERROR(VLOOKUP(A44,'Distributor List'!$A$2:$D$77,3,0),"-") -> North-1 | D44: =IFERROR(VLOOKUP(A44,'Distributor List'!$A$2:$F$77,6,0),"-") -> Pak-2 | E44: =IFERROR(VLOOKUP(A44,'Distributor List'!$A$2:$D$77,4,0),"-") -> Distributor | F44: =IFERROR(VLOOKUP(H44,'Price List'!$A$2:$H$109,8,0),"-") -> Medicronis | G44: =IFERROR(VLOOKUP(A44,'Distributor List'!$A$2:$E$77,5,0),"-") -> Bannu Vacant | H44: Medizek 40mg | I44: 105 | J44: 0 | K44: 0 | L44: =J44*I44 -> 0 | M44: =K44*I44 -> 0 | N44: 0 | O44: =N44*I44 -> 0 | P44: =L44-O44 -> 0 | Q44: 0 | R44: 0 | S44: =IFERROR(L44/R44,"-") -> - | T44: 0 | U44: 0 | V44: =T44*I44 -> 0 | W44: =L44-V44 -> 0 | X44: =IFERROR(L44/V44-1,"-") -> - | Y44: =(J44)/1*1.5 -> 0 | Z44: =IF(Y44>K44,Y44-K44,0) -> 0 | AA44: =Z44*I44 -> 0 | AB44: =IF(Y44<K44,K44-Y44,0) -> 0 | AC44: =AB44*I44 -> 0 | AD44: =Y44*I44 -> 0 | AE44: 0
A45: AL-HARAM ENTERPRISES, Kohat | B45: =IFERROR(VLOOKUP(A45,'Distributor List'!$A$2:$D$77,2,0),"-") -> Kohat | C45: =IFERROR(VLOOKUP(A45,'Distributor List'!$A$2:$D$77,3,0),"-") -> North-1 | D45: =IFERROR(VLOOKUP(A45,'Distributor List'!$A$2:$F$77,6,0),"-") -> Pak-2 | E45: =IFERROR(VLOOKUP(A45,'Distributor List'!$A$2:$D$77,4,0),"-") -> Distributor | F45: =IFERROR(VLOOKUP(H45,'Price List'!$A$2:$H$109,8,0),"-") -> Medicronis | G45: =IFERROR(VLOOKUP(A45,'Distributor List'!$A$2:$E$77,5,0),"-") -> Bannu Vacant | H45: Medizek INJ | I45: 120 | J45: 0 | K45: 0 | L45: =J45*I45 -> 0 | M45: =K45*I45 -> 0 | N45: 0 | O45: =N45*I45 -> 0 | P45: =L45-O45 -> 0 | Q45: 0 | R45: 0 | S45: =IFERROR(L45/R45,"-") -> - | T45: 0 | U45: 0 | V45: =T45*I45 -> 0 | W45: =L45-V45 -> 0 | X45: =IFERROR(L45/V45-1,"-") -> - | Y45: =(J45)/1*1.5 -> 0 | Z45: =IF(Y45>K45,Y45-K45,0) -> 0 | AA45: =Z45*I45 -> 0 | AB45: =IF(Y45<K45,K45-Y45,0) -> 0 | AC45: =AB45*I45 -> 0 | AD45: =Y45*I45 -> 0 | AE45: 0
A46: AL-HARAM ENTERPRISES, Kohat | B46: =IFERROR(VLOOKUP(A46,'Distributor List'!$A$2:$D$77,2,0),"-") -> Kohat | C46: =IFERROR(VLOOKUP(A46,'Distributor List'!$A$2:$D$77,3,0),"-") -> North-1 | D46: =IFERROR(VLOOKUP(A46,'Distributor List'!$A$2:$F$77,6,0),"-") -> Pak-2 | E46: =IFERROR(VLOOKUP(A46,'Distributor List'!$A$2:$D$77,4,0),"-") -> Distributor | F46: =IFERROR(VLOOKUP(H46,'Price List'!$A$2:$H$109,8,0),"-") -> Medicronis | G46: =IFERROR(VLOOKUP(A46,'Distributor List'!$A$2:$E$77,5,0),"-") -> Bannu Vacant | H46: Paxcal Syrup 120ml | I46: 105 | J46: 10 | K46: 113 | L46: =J46*I46 -> 1050 | M46: =K46*I46 -> 11865 | N46: 10 | O46: =N46*I46 -> 1050 | P46: =L46-O46 -> 0 | Q46: 75 | R46: =Q46*I46 -> 7875 | S46: =IFERROR(L46/R46,"-") -> 0.13333333 | T46: 15 | U46: =J46-T46 -> -5 | V46: =T46*I46 -> 1575 | W46: =L46-V46 -> -525 | X46: =IFERROR(L46/V46-1,"-") -> -0.33333333 | Y46: =(J46)/1*1.5 -> 15 | Z46: =IF(Y46>K46,Y46-K46,0) -> 0 | AA46: =Z46*I46 -> 0 | AB46: =IF(Y46<K46,K46-Y46,0) -> 98 | AC46: =AB46*I46 -> 10290 | AD46: =Y46*I46 -> 1575 | AE46: 0
A47: AL-HARAM ENTERPRISES, Kohat | B47: =IFERROR(VLOOKUP(A47,'Distributor List'!$A$2:$D$77,2,0),"-") -> Kohat | C47: =IFERROR(VLOOKUP(A47,'Distributor List'!$A$2:$D$77,3,0),"-") -> North-1 | D47: =IFERROR(VLOOKUP(A47,'Distributor List'!$A$2:$F$77,6,0),"-") -> Pak-2 | E47: =IFERROR(VLOOKUP(A47,'Distributor List'!$A$2:$D$77,4,0),"-") -> Distributor | F47: =IFERROR(VLOOKUP(H47,'Price List'!$A$2:$H$109,8,0),"-") -> Medicronis | G47: =IFERROR(VLOOKUP(A47,'Distributor List'!$A$2:$E$77,5,0),"-") -> Bannu Vacant | H47: Paxcal Tab 20's | I47: 170 | J47: 3 | K47: 28 | L47: =J47*I47 -> 510 | M47: =K47*I47 -> 4760 | N47: 3 | O47: =N47*I47 -> 510 | P47: =L47-O47 -> 0 | Q47: 75 | R47: =Q47*I47 -> 12750 | S47: =IFERROR(L47/R47,"-") -> 0.04 | T47: 5 | U47: =J47-T47 -> -2 | V47: =T47*I47 -> 850 | W47: =L47-V47 -> -340 | X47: =IFERROR(L47/V47-1,"-") -> -0.4 | Y47: =(J47)/1*1.5 -> 4.5 | Z47: =IF(Y47>K47,Y47-K47,0) -> 0 | AA47: =Z47*I47 -> 0 | AB47: =IF(Y47<K47,K47-Y47,0) -> 23.5 | AC47: =AB47*I47 -> 3995 | AD47: =Y47*I47 -> 765 | AE47: 0
A48: AL-HARAM ENTERPRISES, Kohat | B48: =IFERROR(VLOOKUP(A48,'Distributor List'!$A$2:$D$77,2,0),"-") -> Kohat | C48: =IFERROR(VLOOKUP(A48,'Distributor List'!$A$2:$D$77,3,0),"-") -> North-1 | D48: =IFERROR(VLOOKUP(A48,'Distributor List'!$A$2:$F$77,6,0),"-") -> Pak-2 | E48: =IFERROR(VLOOKUP(A48,'Distributor List'!$A$2:$D$77,4,0),"-") -> Distributor | F48: =IFERROR(VLOOKUP(H48,'Price List'!$A$2:$H$109,8,0),"-") -> Medicronis | G48: =IFERROR(VLOOKUP(A48,'Distributor List'!$A$2:$E$77,5,0),"-") -> Bannu Vacant | H48: V-Fol 400mcg | I48: 120 | J48: 65 | K48: 0 | L48: =J48*I48 -> 7800 | M48: =K48*I48 -> 0 | N48: 65 | O48: =N48*I48 -> 7800 | P48: =L48-O48 -> 0 | Q48: 81 | R48: =Q48*I48 -> 9720 | S48: =IFERROR(L48/R48,"-") -> 0.80246914 | T48: 52 | U48: =J48-T48 -> 13 | V48: =T48*I48 -> 6240 | W48: =L48-V48 -> 1560 | X48: =IFERROR(L48/V48-1,"-") -> 0.25 | Y48: =(J48)/1*1.5 -> 97.5 | Z48: =IF(Y48>K48,Y48-K48,0) -> 97.5 | AA48: =Z48*I48 -> 11700 | AB48: =IF(Y48<K48,K48-Y48,0) -> 0 | AC48: =AB48*I48 -> 0 | AD48: =Y48*I48 -> 11700 | AE48: 0
A49: MEHRAN TRADERS, Mardan | B49: =IFERROR(VLOOKUP(A49,'Distributor List'!$A$2:$D$77,2,0),"-") -> Mardan | C49: =IFERROR(VLOOKUP(A49,'Distributor List'!$A$2:$D$77,3,0),"-") -> North-2 | D49: =IFERROR(VLOOKUP(A49,'Distributor List'!$A$2:$F$77,6,0),"-") -> Pak-2 | E49: =IFERROR(VLOOKUP(A49,'Distributor List'!$A$2:$D$77,4,0),"-") -> Distributor | F49: =IFERROR(VLOOKUP(H49,'Price List'!$A$2:$H$109,8,0),"-") -> Medicronis | G49: =IFERROR(VLOOKUP(A49,'Distributor List'!$A$2:$E$77,5,0),"-") -> Rooh Ul Ameen | H49: Novagen 250mg | I49: 54 | J49: 0 | K49: 0 | L49: =J49*I49 -> 0 | M49: =K49*I49 -> 0 | N49: 0 | O49: =N49*I49 -> 0 | P49: =L49-O49 -> 0 | Q49: 172.8 | R49: =Q49*I49 -> 9331.2 | S49: =IFERROR(L49/R49,"-") -> 0 | T49: 0 | U49: =J49-T49 -> 0 | V49: =T49*I49 -> 0 | W49: =L49-V49 -> 0 | X49: =IFERROR(L49/V49-1,"-") -> - | Y49: =(J49)/1*1.5 -> 0 | Z49: =IF(Y49>K49,Y49-K49,0) -> 0 | AA49: =Z49*I49 -> 0 | AB49: =IF(Y49<K49,K49-Y49,0) -> 0 | AC49: =AB49*I49 -> 0 | AD49: =Y49*I49 -> 0 | AE49: 0
A50: MEHRAN TRADERS, Mardan | B50: =IFERROR(VLOOKUP(A50,'Distributor List'!$A$2:$D$77,2,0),"-") -> Mardan | C50: =IFERROR(VLOOKUP(A50,'Distributor List'!$A$2:$D$77,3,0),"-") -> North-2 | D50: =IFERROR(VLOOKUP(A50,'Distributor List'!$A$2:$F$77,6,0),"-") -> Pak-2 | E50: =IFERROR(VLOOKUP(A50,'Distributor List'!$A$2:$D$77,4,0),"-") -> Distributor | F50: =IFERROR(VLOOKUP(H50,'Price List'!$A$2:$H$109,8,0),"-") -> Medicronis | G50: =IFERROR(VLOOKUP(A50,'Distributor List'!$A$2:$E$77,5,0),"-") -> Rooh Ul Ameen | H50: Novagen 500mg | I50: 72 | J50: 0 | K50: 131 | L50: =J50*I50 -> 0 | M50: =K50*I50 -> 9432 | N50: 0 | O50: =N50*I50 -> 0 | P50: =L50-O50 -> 0 | Q50: 414.72 | R50: =Q50*I50 -> 29859.84 | S50: =IFERROR(L50/R50,"-") -> 0 | T50: 0 | U50: =J50-T50 -> 0 | V50: =T50*I50 -> 0 | W50: =L50-V50 -> 0 | X50: =IFERROR(L50/V50-1,"-") -> - | Y50: =(J50)/1*1.5 -> 0 | Z50: =IF(Y50>K50,Y50-K50,0) -> 0 | AA50: =Z50*I50 -> 0 | AB50: =IF(Y50<K50,K50-Y50,0) -> 131 | AC50: =AB50*I50 -> 9432 | AD50: =Y50*I50 -> 0 | AE50: 0
A51: MEHRAN TRADERS, Mardan | B51: =IFERROR(VLOOKUP(A51,'Distributor List'!$A$2:$D$77,2,0),"-") -> Mardan | C51: =IFERROR(VLOOKUP(A51,'Distributor List'!$A$2:$D$77,3,0),"-") -> North-2 | D51: =IFERROR(VLOOKUP(A51,'Distributor List'!$A$2:$F$77,6,0),"-") -> Pak-2 | E51: =IFERROR(VLOOKUP(A51,'Distributor List'!$A$2:$D$77,4,0),"-") -> Distributor | F51: =IFERROR(VLOOKUP(H51,'Price List'!$A$2:$H$109,8,0),"-") -> Medicronis | G51: =IFERROR(VLOOKUP(A51,'Distributor List'!$A$2:$E$77,5,0),"-") -> Rooh Ul Ameen | H51: Novagen 1g | I51: 95 | J51: 0 | K51: 254 | L51: =J51*I51 -> 0 | M51: =K51*I51 -> 24130 | N51: 0 | O51: =N51*I51 -> 0 | P51: =L51-O51 -> 0 | Q51: 829.44 | R51: =Q51*I51 -> 78796.8 | S51: =IFERROR(L51/R51,"-") -> 0 | T51: 0 | U51: =J51-T51 -> 0 | V51: =T51*I51 -> 0 | W51: =L51-V51 -> 0 | X51: =IFERROR(L51/V51-1,"-") -> - | Y51: =(J51)/1*1.5 -> 0 | Z51: =IF(Y51>K51,Y51-K51,0) -> 0 | AA51: =Z51*I51 -> 0 | AB51: =IF(Y51<K51,K51-Y51,0) -> 254 | AC51: =AB51*I51 -> 24130 | AD51: =Y51*I51 -> 0 | AE51: 0
A52: MEHRAN TRADERS, Mardan | B52: =IFERROR(VLOOKUP(A52,'Distributor List'!$A$2:$D$77,2,0),"-") -> Mardan | C52: =IFERROR(VLOOKUP(A52,'Distributor List'!$A$2:$D$77,3,0),"-") -> North-2 | D52: =IFERROR(VLOOKUP(A52,'Distributor List'!$A$2:$F$77,6,0),"-") -> Pak-2 | E52: =IFERROR(VLOOKUP(A52,'Distributor List'!$A$2:$D$77,4,0),"-") -> Distributor | F52: =IFERROR(VLOOKUP(H52,'Price List'!$A$2:$H$109,8,0),"-") -> Transformer | G52: =IFERROR(VLOOKUP(A52,'Distributor List'!$A$2:$E$77,5,0),"-") -> Rooh Ul Ameen | H52: Ectafin 1G | I52: 391 | J52: 0 | K52: 4 | L52: =J52*I52 -> 0 | M52: =K52*I52 -> 1564 | N52: 0 | O52: =N52*I52 -> 0 | P52: =L52-O52 -> 0 | Q52: 0 | R52: =Q52*I52 -> 0 | S52: =IFERROR(L52/R52,"-") -> - | T52: 0 | U52: =J52-T52 -> 0 | V52: =T52*I52 -> 0 | W52: =L52-V52 -> 0 | X52: =IFERROR(L52/V52-1,"-") -> - | Y52: =(J52)/1*1.5 -> 0 | Z52: =IF(Y52>K52,Y52-K52,0) -> 0 | AA52: =Z52*I52 -> 0 | AB52: =IF(Y52<K52,K52-Y52,0) -> 4 | AC52: =AB52*I52 -> 1564 | AD52: =Y52*I52 -> 0 | AE52: 0
A53: MEHRAN TRADERS, Mardan | B53: =IFERROR(VLOOKUP(A53,'Distributor List'!$A$2:$D$77,2,0),"-") -> Mardan | C53: =IFERROR(VLOOKUP(A53,'Distributor List'!$A$2:$D$77,3,0),"-") -> North-2 | D53: =IFERROR(VLOOKUP(A53,'Distributor List'!$A$2:$F$77,6,0),"-") -> Pak-2 | E53: =IFERROR(VLOOKUP(A53,'Distributor List'!$A$2:$D$77,4,0),"-") -> Distributor | F53: =IFERROR(VLOOKUP(H53,'Price List'!$A$2:$H$109,8,0),"-") -> Transformer | G53: =IFERROR(VLOOKUP(A53,'Distributor List'!$A$2:$E$77,5,0),"-") -> Rooh Ul Ameen | H53: Ectafin 2G | I53: 616.25 | J53: 0 | K53: 5 | L53: =J53*I53 -> 0 | M53: =K53*I53 -> 3081.25 | N53: 0 | O53: =N53*I53 -> 0 | P53: =L53-O53 -> 0 | Q53: 0 | R53: =Q53*I53 -> 0 | S53: =IFERROR(L53/R53,"-") -> - | T53: 0 | U53: =J53-T53 -> 0 | V53: =T53*I53 -> 0 | W53: =L53-V53 -> 0 | X53: =IFERROR(L53/V53-1,"-") -> - | Y53: =(J53)/1*1.5 -> 0 | Z53: =IF(Y53>K53,Y53-K53,0) -> 0 | AA53: =Z53*I53 -> 0 | AB53: =IF(Y53<K53,K53-Y53,0) -> 5 | AC53: =AB53*I53 -> 3081.25 | AD53: =Y53*I53 -> 0 | AE53: 0
A54: MEHRAN TRADERS, Mardan | B54: =IFERROR(VLOOKUP(A54,'Distributor List'!$A$2:$D$77,2,0),"-") -> Mardan | C54: =IFERROR(VLOOKUP(A54,'Distributor List'!$A$2:$D$77,3,0),"-") -> North-2 | D54: =IFERROR(VLOOKUP(A54,'Distributor List'!$A$2:$F$77,6,0),"-") -> Pak-2 | E54: =IFERROR(VLOOKUP(A54,'Distributor List'!$A$2:$D$77,4,0),"-") -> Distributor | F54: =IFERROR(VLOOKUP(H54,'Price List'!$A$2:$H$109,8,0),"-") -> Medicronis | G54: =IFERROR(VLOOKUP(A54,'Distributor List'!$A$2:$E$77,5,0),"-") -> Rooh Ul Ameen | H54: Lancix Inj. 10s | I54: 270 | J54: 0 | K54: 397 | L54: =J54*I54 -> 0 | M54: =K54*I54 -> 107190 | N54: 1 | O54: =N54*I54 -> 270 | P54: =L54-O54 -> -270 | Q54: 84 | R54: =Q54*I54 -> 22680 | S54: =IFERROR(L54/R54,"-") -> 0 | T54: -3 | U54: =J54-T54 -> 3 | V54: =T54*I54 -> -810 | W54: =L54-V54 -> 810 | X54: =IFERROR(L54/V54-1,"-") -> -1 | Y54: =(J54)/1*1.5 -> 0 | Z54: =IF(Y54>K54,Y54-K54,0) -> 0 | AA54: =Z54*I54 -> 0 | AB54: =IF(Y54<K54,K54-Y54,0) -> 397 | AC54: =AB54*I54 -> 107190 | AD54: =Y54*I54 -> 0 | AE54: 0
A55: MEHRAN TRADERS, Mardan | B55: =IFERROR(VLOOKUP(A55,'Distributor List'!$A$2:$D$77,2,0),"-") -> Mardan | C55: =IFERROR(VLOOKUP(A55,'Distributor List'!$A$2:$D$77,3,0),"-") -> North-2 | D55: =IFERROR(VLOOKUP(A55,'Distributor List'!$A$2:$F$77,6,0),"-") -> Pak-2 | E55: =IFERROR(VLOOKUP(A55,'Distributor List'!$A$2:$D$77,4,0),"-") -> Distributor | F55: =IFERROR(VLOOKUP(H55,'Price List'!$A$2:$H$109,8,0),"-") -> Medicronis | G55: =IFERROR(VLOOKUP(A55,'Distributor List'!$A$2:$E$77,5,0),"-") -> Rooh Ul Ameen | H55: Lancix Inj. 25s | I55: 670 | J55: 1 | K55: 164 | L55: =J55*I55 -> 670 | M55: =K55*I55 -> 109880 | N55: 0 | O55: =N55*I55 -> 0 | P55: =L55-O55 -> 670 | Q55: 42 | R55: =Q55*I55 -> 28140 | S55: =IFERROR(L55/R55,"-") -> 0.023809524 | T55: 2 | U55: =J55-T55 -> -1 | V55: =T55*I55 -> 1340 | W55: =L55-V55 -> -670 | X55: =IFERROR(L55/V55-1,"-") -> -0.5 | Y55: =(J55)/1*1.5 -> 1.5 | Z55: =IF(Y55>K55,Y55-K55,0) -> 0 | AA55: =Z55*I55 -> 0 | AB55: =IF(Y55<K55,K55-Y55,0) -> 162.5 | AC55: =AB55*I55 -> 108875 | AD55: =Y55*I55 -> 1005 | AE55: 0
A56: MEHRAN TRADERS, Mardan | B56: =IFERROR(VLOOKUP(A56,'Distributor List'!$A$2:$D$77,2,0),"-") -> Mardan | C56: =IFERROR(VLOOKUP(A56,'Distributor List'!$A$2:$D$77,3,0),"-") -> North-2 | D56: =IFERROR(VLOOKUP(A56,'Distributor List'!$A$2:$F$77,6,0),"-") -> Pak-2 | E56: =IFERROR(VLOOKUP(A56,'Distributor List'!$A$2:$D$77,4,0),"-") -> Distributor | F56: =IFERROR(VLOOKUP(H56,'Price List'!$A$2:$H$109,8,0),"-") -> Medicronis | G56: =IFERROR(VLOOKUP(A56,'Distributor List'!$A$2:$E$77,5,0),"-") -> Rooh Ul Ameen | H56: G.Tax 250mg | I56: 58 | J56: 0 | K56: 221 | L56: =J56*I56 -> 0 | M56: =K56*I56 -> 12818 | N56: 0 | O56: =N56*I56 -> 0 | P56: =L56-O56 -> 0 | Q56: 83.34 | R56: =Q56*I56 -> 4833.72 | S56: =IFERROR(L56/R56,"-") -> 0 | T56: 0 | U56: =J56-T56 -> 0 | V56: =T56*I56 -> 0 | W56: =L56-V56 -> 0 | X56: =IFERROR(L56/V56-1,"-") -> - | Y56: =(J56)/1*1.5 -> 0 | Z56: =IF(Y56>K56,Y56-K56,0) -> 0 | AA56: =Z56*I56 -> 0 | AB56: =IF(Y56<K56,K56-Y56,0) -> 221 | AC56: =AB56*I56 -> 12818 | AD56: =Y56*I56 -> 0 | AE56: 0
A57: MEHRAN TRADERS, Mardan | B57: =IFERROR(VLOOKUP(A57,'Distributor List'!$A$2:$D$77,2,0),"-") -> Mardan | C57: =IFERROR(VLOOKUP(A57,'Distributor List'!$A$2:$D$77,3,0),"-") -> North-2 | D57: =IFERROR(VLOOKUP(A57,'Distributor List'!$A$2:$F$77,6,0),"-") -> Pak-2 | E57: =IFERROR(VLOOKUP(A57,'Distributor List'!$A$2:$D$77,4,0),"-") -> Distributor | F57: =IFERROR(VLOOKUP(H57,'Price List'!$A$2:$H$109,8,0),"-") -> Medicronis | G57: =IFERROR(VLOOKUP(A57,'Distributor List'!$A$2:$E$77,5,0),"-") -> Rooh Ul Ameen | H57: G.Tax 500mg | I57: 56 | J57: 0 | K57: 23 | L57: =J57*I57 -> 0 | M57: =K57*I57 -> 1288 | N57: 0 | O57: =N57*I57 -> 0 | P57: =L57-O57 -> 0 | Q57: 80.37 | R57: =Q57*I57 -> 4500.72 | S57: =IFERROR(L57/R57,"-") -> 0 | T57: 0 | U57: =J57-T57 -> 0 | V57: =T57*I57 -> 0 | W57: =L57-V57 -> 0 | X57: =IFERROR(L57/V57-1,"-") -> - | Y57: =(J57)/1*1.5 -> 0 | Z57: =IF(Y57>K57,Y57-K57,0) -> 0 | AA57: =Z57*I57 -> 0 | AB57: =IF(Y57<K57,K57-Y57,0) -> 23 | AC57: =AB57*I57 -> 1288 | AD57: =Y57*I57 -> 0 | AE57: 0
... A66: MEHRAN TRADERS, Mardan | B66: =IFERROR(VLOOKUP(A66,'Distributor List'!$A$2:$D$77,2,0),"-") -> Mardan | C66: =IFERROR(VLOOKUP(A66,'Distributor List'!$A$2:$D$77,3,0),"-") -> North-2 | D66: =IFERROR(VLOOKUP(A66,'Distributor List'!$A$2:$F$77,6,0),"-") -> Pak-2 | E66: =IFERROR(VLOOKUP(A66,'Distributor List'!$A$2:$D$77,4,0),"-") -> Distributor | F66: =IFERROR(VLOOKUP(H66,'Price List'!$A$2:$H$109,8,0),"-") -> Medicronis | G66: =IFERROR(VLOOKUP(A66,'Distributor List'!$A$2:$E$77,5,0),"-") -> Rooh Ul Ameen | H66: Hostenil Syrup 120ml | I66: 90 | J66: 0 | K66: 11 | L66: =J66*I66 -> 0 | M66: =K66*I66 -> 990 | N66: 0 | O66: =N66*I66 -> 0 | P66: =L66-O66 -> 0 | Q66: 0 | R66: =Q66*I66 -> 0 | S66: =IFERROR(L66/R66,"-") -> - | T66: 0 | U66: =J66-T66 -> 0 | V66: =T66*I66 -> 0 | W66: =L66-V66 -> 0 | X66: =IFERROR(L66/V66-1,"-") -> - | Y66: =(J66)/1*1.5 -> 0 | Z66: =IF(Y66>K66,Y66-K66,0) -> 0 | AA66: =Z66*I66 -> 0 | AB66: =IF(Y66<K66,K66-Y66,0) -> 11 | AC66: =AB66*I66 -> 990 | AD66: =Y66*I66 -> 0 | AE66: 0
A67: MEHRAN TRADERS, Mardan | B67: =IFERROR(VLOOKUP(A67,'Distributor List'!$A$2:$D$77,2,0),"-") -> Mardan | C67: =IFERROR(VLOOKUP(A67,'Distributor List'!$A$2:$D$77,3,0),"-") -> North-2 | D67: =IFERROR(VLOOKUP(A67,'Distributor List'!$A$2:$F$77,6,0),"-") -> Pak-2 | E67: =IFERROR(VLOOKUP(A67,'Distributor List'!$A$2:$D$77,4,0),"-") -> Distributor | F67: =IFERROR(VLOOKUP(H67,'Price List'!$A$2:$H$109,8,0),"-") -> Medicronis | G67: =IFERROR(VLOOKUP(A67,'Distributor List'!$A$2:$E$77,5,0),"-") -> Rooh Ul Ameen | H67: kufxy Syp 120ml | I67: 99 | J67: 10 | K67: 327 | L67: =J67*I67 -> 990 | N67: 15 | O67: =N67*I67 -> 1485 | P67: =L67-O67 -> -495 | Q67: 84 | R67: =Q67*I67 -> 8316 | S67: =IFERROR(L67/R67,"-") -> 0.11904762 | T67: 13 | U67: =J67-T67 -> -3 | V67: =T67*I67 -> 1287 | W67: =L67-V67 -> -297 | X67: =IFERROR(L67/V67-1,"-") -> -0.23076923 | Y67: =(J67)/1*1.5 -> 15 | Z67: =IF(Y67>K67,Y67-K67,0) -> 0 | AA67: =Z67*I67 -> 0 | AB67: =IF(Y67<K67,K67-Y67,0) -> 312 | AC67: =AB67*I67 -> 30888 | AD67: =Y67*I67 -> 1485
A68: MEHRAN TRADERS, Mardan | B68: =IFERROR(VLOOKUP(A68,'Distributor List'!$A$2:$D$77,2,0),"-") -> Mardan | C68: =IFERROR(VLOOKUP(A68,'Distributor List'!$A$2:$D$77,3,0),"-") -> North-2 | D68: =IFERROR(VLOOKUP(A68,'Distributor List'!$A$2:$F$77,6,0),"-") -> Pak-2 | E68: =IFERROR(VLOOKUP(A68,'Distributor List'!$A$2:$D$77,4,0),"-") -> Distributor | F68: =IFERROR(VLOOKUP(H68,'Price List'!$A$2:$H$109,8,0),"-") -> Medicronis | G68: =IFERROR(VLOOKUP(A68,'Distributor List'!$A$2:$E$77,5,0),"-") -> Rooh Ul Ameen | H68: Salberry Sachet 10s | I68: 105 | J68: 0 | K68: 67 | L68: =J68*I68 -> 0 | M68: =K68*I68 -> 7035 | N68: 0 | O68: =N68*I68 -> 0 | P68: =L68-O68 -> 0 | Q68: 0 | R68: =Q68*I68 -> 0 | S68: =IFERROR(L68/R68,"-") -> - | T68: 6 | U68: =J68-T68 -> -6 | V68: =T68*I68 -> 630 | W68: =L68-V68 -> -630 | X68: =IFERROR(L68/V68-1,"-") -> -1 | Y68: =(J68)/1*1.5 -> 0 | Z68: =IF(Y68>K68,Y68-K68,0) -> 0 | AA68: =Z68*I68 -> 0 | AB68: =IF(Y68<K68,K68-Y68,0) -> 67 | AC68: =AB68*I68 -> 7035 | AD68: =Y68*I68 -> 0 | AE68: 0
A69: MEHRAN TRADERS, Mardan | B69: =IFERROR(VLOOKUP(A69,'Distributor List'!$A$2:$D$77,2,0),"-") -> Mardan | C69: =IFERROR(VLOOKUP(A69,'Distributor List'!$A$2:$D$77,3,0),"-") -> North-2 | D69: =IFERROR(VLOOKUP(A69,'Distributor List'!$A$2:$F$77,6,0),"-") -> Pak-2 | E69: =IFERROR(VLOOKUP(A69,'Distributor List'!$A$2:$D$77,4,0),"-") -> Distributor | F69: =IFERROR(VLOOKUP(H69,'Price List'!$A$2:$H$109,8,0),"-") -> Medicronis | G69: =IFERROR(VLOOKUP(A69,'Distributor List'!$A$2:$E$77,5,0),"-") -> Rooh Ul Ameen | H69: Berry Flow Sachet | I69: 115 | J69: 50 | K69: 0 | L69: =J69*I69 -> 5750 | M69: =K69*I69 -> 0 | N69: 50 | O69: =N69*I69 -> 5750 | P69: =L69-O69 -> 0 | Q69: 72 | R69: =Q69*I69 -> 8280 | S69: =IFERROR(L69/R69,"-") -> 0.69444444 | T69: 0 | U69: =J69-T69 -> 50 | V69: =T69*I69 -> 0 | W69: =L69-V69 -> 5750 | X69: =IFERROR(L69/V69-1,"-") -> - | Y69: =(J69)/1*1.5 -> 75 | Z69: =IF(Y69>K69,Y69-K69,0) -> 75 | AA69: =Z69*I69 -> 8625 | AB69: =IF(Y69<K69,K69-Y69,0) -> 0 | AC69: =AB69*I69 -> 0 | AD69: =Y69*I69 -> 8625 | AE69: 0
A70: MEHRAN TRADERS, Mardan | B70: =IFERROR(VLOOKUP(A70,'Distributor List'!$A$2:$D$77,2,0),"-") -> Mardan | C70: =IFERROR(VLOOKUP(A70,'Distributor List'!$A$2:$D$77,3,0),"-") -> North-2 | D70: =IFERROR(VLOOKUP(A70,'Distributor List'!$A$2:$F$77,6,0),"-") -> Pak-2 | E70: =IFERROR(VLOOKUP(A70,'Distributor List'!$A$2:$D$77,4,0),"-") -> Distributor | F70: =IFERROR(VLOOKUP(H70,'Price List'!$A$2:$H$109,8,0),"-") -> Medicronis | G70: =IFERROR(VLOOKUP(A70,'Distributor List'!$A$2:$E$77,5,0),"-") -> Rooh Ul Ameen | H70: Cipak 200mg/100ml Inf | I70: 102 | J70: 0 | K70: 1 | L70: =J70*I70 -> 0 | M70: =K70*I70 -> 102 | N70: 0 | O70: =N70*I70 -> 0 | P70: =L70-O70 -> 0 | Q70: 316.4925 | R70: =Q70*I70 -> 32282.235 | S70: =IFERROR(L70/R70,"-") -> 0 | T70: 0 | U70: =J70-T70 -> 0 | V70: =T70*I70 -> 0 | W70: =L70-V70 -> 0 | X70: =IFERROR(L70/V70-1,"-") -> - | Y70: =(J70)/1*1.5 -> 0 | Z70: =IF(Y70>K70,Y70-K70,0) -> 0 | AA70: =Z70*I70 -> 0 | AB70: =IF(Y70<K70,K70-Y70,0) -> 1 | AC70: =AB70*I70 -> 102 | AD70: =Y70*I70 -> 0 | AE70: 0
A71: MEHRAN TRADERS, Mardan | B71: =IFERROR(VLOOKUP(A71,'Distributor List'!$A$2:$D$77,2,0),"-") -> Mardan | C71: =IFERROR(VLOOKUP(A71,'Distributor List'!$A$2:$D$77,3,0),"-") -> North-2 | D71: =IFERROR(VLOOKUP(A71,'Distributor List'!$A$2:$F$77,6,0),"-") -> Pak-2 | E71: =IFERROR(VLOOKUP(A71,'Distributor List'!$A$2:$D$77,4,0),"-") -> Distributor | F71: =IFERROR(VLOOKUP(H71,'Price List'!$A$2:$H$109,8,0),"-") -> Transformer | G71: =IFERROR(VLOOKUP(A71,'Distributor List'!$A$2:$E$77,5,0),"-") -> Rooh Ul Ameen | H71: Maxy 400mg/250ml Inf | I71: 299 | J71: 0 | K71: 10 | L71: =J71*I71 -> 0 | M71: =K71*I71 -> 2990 | N71: 0 | O71: =N71*I71 -> 0 | P71: =L71-O71 -> 0 | Q71: 0 | R71: =Q71*I71 -> 0 | S71: =IFERROR(L71/R71,"-") -> - | T71: 0 | U71: =J71-T71 -> 0 | V71: =T71*I71 -> 0 | W71: =L71-V71 -> 0 | X71: =IFERROR(L71/V71-1,"-") -> - | Y71: =(J71)/1*1.5 -> 0 | Z71: =IF(Y71>K71,Y71-K71,0) -> 0 | AA71: =Z71*I71 -> 0 | AB71: =IF(Y71<K71,K71-Y71,0) -> 10 | AC71: =AB71*I71 -> 2990 | AD71: =Y71*I71 -> 0 | AE71: 0
A72: MEHRAN TRADERS, Mardan | B72: =IFERROR(VLOOKUP(A72,'Distributor List'!$A$2:$D$77,2,0),"-") -> Mardan | C72: =IFERROR(VLOOKUP(A72,'Distributor List'!$A$2:$D$77,3,0),"-") -> North-2 | D72: =IFERROR(VLOOKUP(A72,'Distributor List'!$A$2:$F$77,6,0),"-") -> Pak-2 | E72: =IFERROR(VLOOKUP(A72,'Distributor List'!$A$2:$D$77,4,0),"-") -> Distributor | F72: =IFERROR(VLOOKUP(H72,'Price List'!$A$2:$H$109,8,0),"-") -> Transformer | G72: =IFERROR(VLOOKUP(A72,'Distributor List'!$A$2:$E$77,5,0),"-") -> Rooh Ul Ameen | H72: Evox 500mg/100ml Inf | I72: 403.75 | J72: 0 | K72: 1 | L72: =J72*I72 -> 0 | M72: =K72*I72 -> 403.75 | N72: 0 | O72: =N72*I72 -> 0 | P72: =L72-O72 -> 0 | Q72: 0 | R72: =Q72*I72 -> 0 | S72: =IFERROR(L72/R72,"-") -> - | T72: 0 | U72: =J72-T72 -> 0 | V72: =T72*I72 -> 0 | W72: =L72-V72 -> 0 | X72: =IFERROR(L72/V72-1,"-") -> - | Y72: =(J72)/1*1.5 -> 0 | Z72: =IF(Y72>K72,Y72-K72,0) -> 0 | AA72: =Z72*I72 -> 0 | AB72: =IF(Y72<K72,K72-Y72,0) -> 1 | AC72: =AB72*I72 -> 403.75 | AD72: =Y72*I72 -> 0 | AE72: 0
